Workbook
Name Slicer_Product_Category1: #N/A
Name Slicer_Region: #N/A
Name Slicer_Region1: #N/A

Sheet Sales_Performance_Analysis.csv
A1: order id | B1: Order Date | C1: Region | D1: Product Category | E1: Sales Amount | F1: Quantity Sold | G1: Discount (%) | H1: Profit
A2: ab899d2f | B2: 45022 | C2: norTh | D2: groceries | E2: 859.29 | F2: 44 | G2: 37 | H2: 1653.87
A3: 73484eb1 | B3: 45412 | C3: Mes$t | D3: groceries | E3: 1546.81 | F3: 23 | G3: 33 | H3: 1932.71
A4: 19395924 | B4: 45363 | C4: eAsT | D4: groceries | E4: 4703.58 | F4: 31 | G4: 15 | H4: 527.47
A5: b3fded3d | B5: 45331 | C5: eAsT | D5: groceries | E5: 3377.17 | F5: 47 | G5: 3 | H5: 482.65
A6: 6e4bdd51 | B6: 45502 | C6: $0uTH | D6: Cloth ing | E6: 3517.49 | F6: 6 | G6: 28 | H6: 748.72
A7: 21d88d69 | B7: 45164 | C7: eAsT | D7: FURNiture | E7: 362.55 | F7: 19 | G7: 50 | H7: 314.71
A8: 9da2704d | B8: 45572 | C8: eAsT | D8: sports | E8: 4811.17 | F8: 22 | G8: 18 | H8: 1372.89
A9: a1bd6815 | B9: 45000 | C9: Mes$t | D9: electronicS | E9: 3565.2 | F9: 22 | G9: 16 | H9: 1437.3
A10: 0bbd51fc | B10: 45106 | C10: eAsT | D10: Cloth ing | E10: 3805.25 | F10: 19 | G10: 3 | H10: 1537.28
A11: 8bf7e4b3 | B11: 44998 | C11: $0uTH | D11: Cloth ing | E11: 2178.72 | F11: 15 | G11: 24 | H11: 1696.65
A12: e6cf1255 | B12: 45439 | C12: Mes$t | D12: groceries | E12: 2844.93 | F12: 34 | G12: 12 | H12: 1166.39
A13: 3ba1fc5c | B13: 45291 | C13: Mes$t | D13: electronicS | E13: 3600.04 | F13: 10 | G13: 2 | H13: 1632.75
A14: 388ff70d | B14: 45239 | C14: eAsT | D14: $port$ | E14: 941.88 | F14: 13 | G14: 28 | H14: 646.49
A15: ce2e9002 | B15: 44919 | C15: $0uTH | D15: $port$ | E15: 3300.86 | F15: 1 | G15: 48 | H15: 86.9
A16: a4f9a338 | B16: 45329 | C16: eAsT | D16: groceries | E16: 1081.62 | F16: 4 | G16: 19 | H16: 611.06
... A19: 35358e9c | B19: 45471 | C19: norTh | D19: Cloth ing | E19: 2784.79 | F19: 35 | G19: 40 | H19: 999.6
A20: 31676338 | B20: 45246 | C20: $0uTH | D20: Cloth ing | E20: 1082.98 | F20: 8 | G20: 11 | H20: 1604.19
A21: 05d72e20 | B21: 45556 | C21: eAsT | D21: Cloth ing | E21: 787.79 | F21: 47 | G21: 18 | H21: 1313.33
A22: 68dbe328 | B22: 45566 | C22: $0uTH | D22: FURNiture | E22: 312.7 | F22: 36 | G22: 43 | H22: 559.52
A23: 78d3f47b | B23: 45077 | C23: eAsT | D23: $port$ | E23: 265.32 | F23: 21 | G23: 36 | H23: 595.91
A24: 9e4d1fe0 | B24: 45400 | C24: Mes$t | D24: FURNiture | E24: 1253.64 | F24: 35 | G24: 14 | H24: 1653.66
A25: 9215a70e | B25: 45341 | C25: Mes$t | D25: Cloth ing | E25: 1874.07 | F25: 28 | G25: 23 | H25: 1783.26
A26: 54ca3433 | B26: 45041 | C26: eAsT | D26: Cloth ing | E26: 2561.71 | F26: 44 | G26: 10
A27: 0ba75cc7 | B27: 45059 | C27: Mes$t | D27: $port$ | E27: 1960.74 | F27: 50 | G27: 6 | H27: 1530.61
A28: 601860b1 | B28: 45037 | C28: eAsT | D28: electronicS | E28: 2415.44 | F28: 35 | G28: 14 | H28: 335.57
A29: e393e106 | B29: 45290 | C29: eAsT | D29: electronicS | E29: 2284.22 | F29: 8 | G29: 41 | H29: 1866.59
A30: 7ab3d472 | B30: 44885 | C30: Mes$t | D30: $port$ | E30: 2118.55 | F30: 29 | G30: 24 | H30: 702.15
A31: 01d9b1ae | B31: 45248 | C31: $0uTH | D31: groceries | E31: 4803.6 | F31: 11 | G31: 12 | H31: 1086.74
A32: 20385cb6 | B32: 45533 | C32: norTh | D32: groceries | E32: 4297 | F32: 17 | G32: 49 | H32: 678.7
A33: 2bfe58fa | B33: 45449 | C33: eAsT | D33: $port$ | E33: 804.64 | F33: 43 | G33: 1 | H33: 60.68
A34: 2800f598 | B34: 45228 | C34: Mes$t | D34: Cloth ing | E34: 2903.83 | F34: 16 | G34: 31 | H34: 27.53
A35: 97d3684e | B35: 45114 | C35: eAsT | D35: electronicS | E35: 3436.78 | F35: 21 | G35: 27 | H35: 75.19
A36: 8a0ce327 | B36: 45557 | C36: $0uTH | D36: electronicS | E36: 581.5 | F36: 39 | G36: 34 | H36: 863
A37: 6ed01fa3 | B37: 45018 | C37: Mes$t | D37: electronicS | E37: 1939.1 | F37: 26 | G37: 47 | H37: 1273.29
A38: 1c109dd7 | B38: 44899 | C38: $0uTH | D38: FURNiture | E38: 3252.47 | F38: 24 | G38: 4 | H38: 1643.65
... A69: 92458ed3 | B69: 45024 | C69: norTh | D69: FURNiture | E69: 1356.62 | F69: 2 | G69: 21 | H69: 1213.34
A70: 76740552 | B70: 45201 | C70: $0uTH | D70: electronicS | E70: 2905.8 | F70: 20 | G70: 10 | H70: 1417.43
A71: f92de80d | B71: 45060 | C71: $0uTH | D71: FURNiture | E71: 2065.42 | F71: 22 | G71: 15 | H71: 787.51
A72: 647ff51a | B72: 45094 | C72: eAsT | D72: Cloth ing | E72: 272.88 | F72: 47 | G72: 29 | H72: 1208.68
...

Sheet Task 8
B3: Sum of Sales Amount | C3: Column Labels
B4: Row Labels | C4: Clothings | D4: Electronics | E4: Furniture | F4: Groceries | G4: Sports | H4: Grand Total
B5: East | C5: 558307.99 | D5: 453722.85 | E5: 558116.9 | F5: 449735.78 | G5: 575612.96 | H5: 2595496.5
B6: North | C6: 575975.88 | D6: 527159.55 | E6: 494993.63 | F6: 471913.51 | G6: 469626.43 | H6: 2539669
B7: South | C7: 529784.9 | D7: 492194.56 | E7: 487656.54 | F7: 496331.25 | G7: 488444.03 | H7: 2494411.3
B8: West | C8: 491938.81 | D8: 574757.97 | E8: 508729.09 | F8: 446244.52 | G8: 458536.54 | H8: 2480206.9
B9: Grand Total | C9: 2156007.6 | D9: 2047834.9 | E9: 2049496.2 | F9: 1864225.1 | G9: 1992220 | H9: 10109784

Sheet Task 2
A1: Order id | B1: Order Date | C1: Region | D1: Product Category | E1: Sales Amount | F1: Quantity Sold | G1: Discount (%) | H1: Profit
A2: {=UPPER(Sales_Performance_Analysis.csv!A2:A4001)} -> AB899D2F | B2: 45022 | C2: North | D2: Groceries | E2: 859.29 | F2: 44 | G2: 37 | H2: 1653.87
A3: 73484EB1 | B3: 45412 | C3: West | D3: Groceries | E3: 1546.81 | F3: 23 | G3: 33 | H3: 1932.71
A4: 19395924 | B4: 45363 | C4: East | D4: Groceries | E4: 4703.58 | F4: 31 | G4: 15 | H4: 527.47
A5: B3FDED3D | B5: 45331 | C5: East | D5: Groceries | E5: 3377.17 | F5: 47 | G5: 3 | H5: 482.65
A6: 6E4BDD51 | B6: 45502 | C6: South | D6: Clothings | E6: 3517.49 | F6: 6 | G6: 28 | H6: 748.72
A7: 21D88D69 | B7: 45164 | C7: East | D7: Furniture | E7: 362.55 | F7: 19 | G7: 50 | H7: 314.71
A8: 9DA2704D | B8: 45572 | C8: East | D8: Sports | E8: 4811.17 | F8: 22 | G8: 18 | H8: 1372.89
A9: A1BD6815 | B9: 45000 | C9: West | D9: Electronics | E9: 3565.2 | F9: 22 | G9: 16 | H9: 1437.3
A10: 0BBD51FC | B10: 45106 | C10: East | D10: Clothings | E10: 3805.25 | F10: 19 | G10: 3 | H10: 1537.28
A11: 8BF7E4B3 | B11: 44998 | C11: South | D11: Clothings | E11: 2178.72 | F11: 15 | G11: 24 | H11: 1696.65
A12: E6CF1255 | B12: 45439 | C12: West | D12: Groceries | E12: 2844.93 | F12: 34 | G12: 12 | H12: 1166.39
A13: 3BA1FC5C | B13: 45291 | C13: West | D13: Electronics | E13: 3600.04 | F13: 10 | G13: 2 | H13: 1632.75
A14: 388FF70D | B14: 45239 | C14: East | D14: Sports | E14: 941.88 | F14: 13 | G14: 28 | H14: 646.49
... A25: 9215A70E | B25: 45341 | C25: West | D25: Clothings | E25: 1874.07 | F25: 28 | G25: 23 | H25: 1783.26
A26: 54CA3433 | B26: 45041 | C26: East | D26: Clothings | E26: 2561.71 | F26: 44 | G26: 10 | H26: =AVERAGE(H2:H25,H27:H4001) -> 1007.9759
A27: 0BA75CC7 | B27: 45059 | C27: West | D27: Sports | E27: 1960.74 | F27: 50 | G27: 6 | H27: 1530.61
A28: 601860B1 | B28: 45037 | C28: East | D28: Electronics | E28: 2415.44 | F28: 35 | G28: 14 | H28: 335.57
A29: E393E106 | B29: 45290 | C29: East | D29: Electronics | E29: 2284.22 | F29: 8 | G29: 41 | H29: 1866.59
A30: 7AB3D472 | B30: 44885 | C30: West | D30: Sports | E30: 2118.55 | F30: 29 | G30: 24 | H30: 702.15
A31: 01D9B1AE | B31: 45248 | C31: South | D31: Groceries | E31: 4803.6 | F31: 11 | G31: 12 | H31: 1086.74
A32: 20385CB6 | B32: 45533 | C32: North | D32: Groceries | E32: 4297 | F32: 17 | G32: 49 | H32: 678.7
A33: 2BFE58FA | B33: 45449 | C33: East | D33: Sports | E33: 804.64 | F33: 43 | G33: 1 | H33: 60.68
A34: 2800F598 | B34: 45228 | C34: West | D34: Clothings | E34: 2903.83 | F34: 16 | G34: 31 | H34: 27.53
A35: 97D3684E | B35: 45114 | C35: East | D35: Electronics | E35: 3436.78 | F35: 21 | G35: 27 | H35: 75.19
A36: 8A0CE327 | B36: 45557 | C36: South | D36: Electronics | E36: 581.5 | F36: 39 | G36: 34 | H36: 863
A37: 6ED01FA3 | B37: 45018 | C37: West | D37: Electronics | E37: 1939.1 | F37: 26 | G37: 47 | H37: 1273.29
A38: 1C109DD7 | B38: 44899 | C38: South | D38: Furniture | E38: 3252.47 | F38: 24 | G38: 4 | H38: 1643.65
... A4001: DA37CF04 | B4001: 45465 | C4001: East | D4001: Furniture | E4001: 2975.86 | F4001: 29 | G4001: 37 | H4001: 1870.61

Sheet Task 10
A1: Order id | B1: Order Date | C1: Region | D1: Product Category | E1: Sales Amount | F1: Quantity Sold | G1: Discount (%) | H1: Profit
A2: {=UPPER(Sales_Performance_Analysis.csv!A2:A4001)} -> AB899D2F | B2: 45022 | C2: North | D2: Groceries | E2: 859.29 | F2: 44 | G2: 37 | H2: 1653.87
A3: 73484EB1 | B3: 45412 | C3: West | D3: Groceries | E3: 1546.81 | F3: 23 | G3: 33 | H3: 1932.71
A4: 19395924 | B4: 45363 | C4: East | D4: Groceries | E4: 4703.58 | F4: 31 | G4: 15 | H4: 527.47
A5: B3FDED3D | B5: 45331 | C5: East | D5: Groceries | E5: 3377.17 | F5: 47 | G5: 3 | H5: 482.65
A6: 6E4BDD51 | B6: 45502 | C6: South | D6: Clothings | E6: 3517.49 | F6: 6 | G6: 28 | H6: 748.72
A7: 21D88D69 | B7: 45164 | C7: East | D7: Furniture | E7: 362.55 | F7: 19 | G7: 50 | H7: 314.71
A8: 9DA2704D | B8: 45572 | C8: East | D8: Sports | E8: 4811.17 | F8: 22 | G8: 18 | H8: 1372.89
A9: A1BD6815 | B9: 45000 | C9: West | D9: Electronics | E9: 3565.2 | F9: 22 | G9: 16 | H9: 1437.3
A10: 0BBD51FC | B10: 45106 | C10: East | D10: Clothings | E10: 3805.25 | F10: 19 | G10: 3 | H10: 1537.28
A11: 8BF7E4B3 | B11: 44998 | C11: South | D11: Clothings | E11: 2178.72 | F11: 15 | G11: 24 | H11: 1696.65
A12: E6CF1255 | B12: 45439 | C12: West | D12: Groceries | E12: 2844.93 | F12: 34 | G12: 12 | H12: 1166.39
A13: 3BA1FC5C | B13: 45291 | C13: West | D13: Electronics | E13: 3600.04 | F13: 10 | G13: 2 | H13: 1632.75
A14: 388FF70D | B14: 45239 | C14: East | D14: Sports | E14: 941.88 | F14: 13 | G14: 28 | H14: 646.49
... A25: 9215A70E | B25: 45341 | C25: West | D25: Clothings | E25: 1874.07 | F25: 28 | G25: 23 | H25: 1783.26
A26: 54CA3433 | B26: 45041 | C26: East | D26: Clothings | E26: 2561.71 | F26: 44 | G26: 10 | H26: =AVERAGE(H2:H25,H27:H4001) -> 1007.9759
A27: 0BA75CC7 | B27: 45059 | C27: West | D27: Sports | E27: 1960.74 | F27: 50 | G27: 6 | H27: 1530.61
A28: 601860B1 | B28: 45037 | C28: East | D28: Electronics | E28: 2415.44 | F28: 35 | G28: 14 | H28: 335.57
A29: E393E106 | B29: 45290 | C29: East | D29: Electronics | E29: 2284.22 | F29: 8 | G29: 41 | H29: 1866.59
A30: 7AB3D472 | B30: 44885 | C30: West | D30: Sports | E30: 2118.55 | F30: 29 | G30: 24 | H30: 702.15
A31: 01D9B1AE | B31: 45248 | C31: South | D31: Groceries | E31: 4803.6 | F31: 11 | G31: 12 | H31: 1086.74
A32: 20385CB6 | B32: 45533 | C32: North | D32: Groceries | E32: 4297 | F32: 17 | G32: 49 | H32: 678.7
A33: 2BFE58FA | B33: 45449 | C33: East | D33: Sports | E33: 804.64 | F33: 43 | G33: 1 | H33: 60.68
A34: 2800F598 | B34: 45228 | C34: West | D34: Clothings | E34: 2903.83 | F34: 16 | G34: 31 | H34: 27.53
A35: 97D3684E | B35: 45114 | C35: East | D35: Electronics | E35: 3436.78 | F35: 21 | G35: 27 | H35: 75.19
A36: 8A0CE327 | B36: 45557 | C36: South | D36: Electronics | E36: 581.5 | F36: 39 | G36: 34 | H36: 863
A37: 6ED01FA3 | B37: 45018 | C37: West | D37: Electronics | E37: 1939.1 | F37: 26 | G37: 47 | H37: 1273.29
A38: 1C109DD7 | B38: 44899 | C38: South | D38: Furniture | E38: 3252.47 | F38: 24 | G38: 4 | H38: 1643.65
... A4001: DA37CF04 | B4001: 45465 | C4001: East | D4001: Furniture | E4001: 2975.86 | F4001: 29 | G4001: 37 | H4001: 1870.61

Sheet Task 3
A1: Order id | B1: Order Date | C1: Region | D1: Product Category | E1: Sales Amount | F1: Quantity Sold | G1: Discount (%) | H1: Profit | J1: Average sale by Region
A2: {=UPPER(Sales_Performance_Analysis.csv!A2:A4001)} -> AB899D2F | B2: 45022 | C2: North | D2: Groceries | E2: 859.29 | F2: 44 | G2: 37 | H2: 1653.87
A3: 73484EB1 | B3: 45412 | C3: West | D3: Groceries | E3: 1546.81 | F3: 23 | G3: 33 | H3: 1932.71 | J3: North | K3: =AVERAGEIF(C:C,C2,E:E) -> 2573.1196
A4: 19395924 | B4: 45363 | C4: East | D4: Groceries | E4: 4703.58 | F4: 31 | G4: 15 | H4: 527.47 | J4: South | K4: =AVERAGEIF(C:C,"South",E:E) -> 2494.4113
A5: B3FDED3D | B5: 45331 | C5: East | D5: Groceries | E5: 3377.17 | F5: 47 | G5: 3 | H5: 482.65 | J5: East | K5: =AVERAGEIF(C:C,"East",E:E) -> 2507.7261
A6: 6E4BDD51 | B6: 45502 | C6: South | D6: Clothings | E6: 3517.49 | F6: 6 | G6: 28 | H6: 748.72 | J6: West | K6: =AVERAGEIF(C:C,"West",E:E) -> 2535.9989
A7: 21D88D69 | B7: 45164 | C7: East | D7: Furniture | E7: 362.55 | F7: 19 | G7: 50 | H7: 314.71
A8: 9DA2704D | B8: 45572 | C8: East | D8: Sports | E8: 4811.17 | F8: 22 | G8: 18 | H8: 1372.89
A9: A1BD6815 | B9: 45000 | C9: West | D9: Electronics | E9: 3565.2 | F9: 22 | G9: 16 | H9: 1437.3
A10: 0BBD51FC | B10: 45106 | C10: East | D10: Clothings | E10: 3805.25 | F10: 19 | G10: 3 | H10: 1537.28
A11: 8BF7E4B3 | B11: 44998 | C11: South | D11: Clothings | E11: 2178.72 | F11: 15 | G11: 24 | H11: 1696.65
A12: E6CF1255 | B12: 45439 | C12: West | D12: Groceries | E12: 2844.93 | F12: 34 | G12: 12 | H12: 1166.39
A13: 3BA1FC5C | B13: 45291 | C13: West | D13: Electronics | E13: 3600.04 | F13: 10 | G13: 2 | H13: 1632.75
A14: 388FF70D | B14: 45239 | C14: East | D14: Sports | E14: 941.88 | F14: 13 | G14: 28 | H14: 646.49
A15: CE2E9002 | B15: 44919 | C15: South | D15: Sports | E15: 3300.86 | F15: 1 | G15: 48 | H15: 86.9
A16: A4F9A338 | B16: 45329 | C16: East | D16: Groceries | E16: 1081.62 | F16: 4 | G16: 19 | H16: 611.06
A17: EADCEAA8 | B17: 45318 | C17: East | D17: Furniture | E17: 3455.67 | F17: 39 | G17: 21 | H17: 208.1
A18: AD7F9DE9 | B18: 45078 | C18: South | D18: Groceries | E18: 2381.51 | F18: 16 | G18: 39 | H18: 1083.96
... A25: 9215A70E | B25: 45341 | C25: West | D25: Clothings | E25: 1874.07 | F25: 28 | G25: 23 | H25: 1783.26
A26: 54CA3433 | B26: 45041 | C26: East | D26: Clothings | E26: 2561.71 | F26: 44 | G26: 10 | H26: =AVERAGE(H2:H25,H27:H4001) -> 1007.9759
A27: 0BA75CC7 | B27: 45059 | C27: West | D27: Sports | E27: 1960.74 | F27: 50 | G27: 6 | H27: 1530.61
A28: 601860B1 | B28: 45037 | C28: East | D28: Electronics | E28: 2415.44 | F28: 35 | G28: 14 | H28: 335.57
A29: E393E106 | B29: 45290 | C29: East | D29: Electronics | E29: 2284.22 | F29: 8 | G29: 41 | H29: 1866.59
A30: 7AB3D472 | B30: 44885 | C30: West | D30: Sports | E30: 2118.55 | F30: 29 | G30: 24 | H30: 702.15
A31: 01D9B1AE | B31: 45248 | C31: South | D31: Groceries | E31: 4803.6 | F31: 11 | G31: 12 | H31: 1086.74
A32: 20385CB6 | B32: 45533 | C32: North | D32: Groceries | E32: 4297 | F32: 17 | G32: 49 | H32: 678.7
A33: 2BFE58FA | B33: 45449 | C33: East | D33: Sports | E33: 804.64 | F33: 43 | G33: 1 | H33: 60.68
A34: 2800F598 | B34: 45228 | C34: West | D34: Clothings | E34: 2903.83 | F34: 16 | G34: 31 | H34: 27.53
A35: 97D3684E | B35: 45114 | C35: East | D35: Electronics | E35: 3436.78 | F35: 21 | G35: 27 | H35: 75.19
A36: 8A0CE327 | B36: 45557 | C36: South | D36: Electronics | E36: 581.5 | F36: 39 | G36: 34 | H36: 863
A37: 6ED01FA3 | B37: 45018 | C37: West | D37: Electronics | E37: 1939.1 | F37: 26 | G37: 47 | H37: 1273.29
A38: 1C109DD7 | B38: 44899 | C38: South | D38: Furniture | E38: 3252.47 | F38: 24 | G38: 4 | H38: 1643.65
... A4001: DA37CF04 | B4001: 45465 | C4001: East | D4001: Furniture | E4001: 2975.86 | F4001: 29 | G4001: 37 | H4001: 1870.61

Sheet Task 4
A1: Order id | B1: Order Date | C1: Region | D1: Product Category | E1: Sales Amount | F1: Quantity Sold | G1: Discount (%) | H1: Profit | J1: Total Sale by Region
A2: {=UPPER(Sales_Performance_Analysis.csv!A2:A4001)} -> AB899D2F | B2: 45022 | C2: North | D2: Groceries | E2: 859.29 | F2: 44 | G2: 37 | H2: 1653.87
A3: 73484EB1 | B3: 45412 | C3: West | D3: Groceries | E3: 1546.81 | F3: 23 | G3: 33 | H3: 1932.71 | J3: North | K3: =SUMIF(C:C,C2,E:E) -> 2539669
A4: 19395924 | B4: 45363 | C4: East | D4: Groceries | E4: 4703.58 | F4: 31 | G4: 15 | H4: 527.47 | J4: South | K4: =SUMIF(C:C,C6,E:E) -> 2494411.3
A5: B3FDED3D | B5: 45331 | C5: East | D5: Groceries | E5: 3377.17 | F5: 47 | G5: 3 | H5: 482.65 | J5: East | K5: =SUMIF(C:C,C4,E:E) -> 2595496.5
A6: 6E4BDD51 | B6: 45502 | C6: South | D6: Clothings | E6: 3517.49 | F6: 6 | G6: 28 | H6: 748.72 | J6: West | K6: =SUMIF(C:C,C3,E:E) -> 2480206.9
A7: 21D88D69 | B7: 45164 | C7: East | D7: Furniture | E7: 362.55 | F7: 19 | G7: 50 | H7: 314.71
A8: 9DA2704D | B8: 45572 | C8: East | D8: Sports | E8: 4811.17 | F8: 22 | G8: 18 | H8: 1372.89
A9: A1BD6815 | B9: 45000 | C9: West | D9: Electronics | E9: 3565.2 | F9: 22 | G9: 16 | H9: 1437.3
A10: 0BBD51FC | B10: 45106 | C10: East | D10: Clothings | E10: 3805.25 | F10: 19 | G10: 3 | H10: 1537.28 | J10: Average discount by category
A11: 8BF7E4B3 | B11: 44998 | C11: South | D11: Clothings | E11: 2178.72 | F11: 15 | G11: 24 | H11: 1696.65
A12: E6CF1255 | B12: 45439 | C12: West | D12: Groceries | E12: 2844.93 | F12: 34 | G12: 12 | H12: 1166.39 | J12: Groceries | K12: =AVERAGEIF(D:D,D2,G:G) -> 24.466667
A13: 3BA1FC5C | B13: 45291 | C13: West | D13: Electronics | E13: 3600.04 | F13: 10 | G13: 2 | H13: 1632.75 | J13: Clothings | K13: =AVERAGEIF(D:D,D6,G:G) -> 24.886659
A14: 388FF70D | B14: 45239 | C14: East | D14: Sports | E14: 941.88 | F14: 13 | G14: 28 | H14: 646.49 | J14: Furniture | K14: =AVERAGEIF(D:D,D7,G:G) -> 25.230392
A15: CE2E9002 | B15: 44919 | C15: South | D15: Sports | E15: 3300.86 | F15: 1 | G15: 48 | H15: 86.9 | J15: Sports | K15: =AVERAGEIF(D:D,D8,G:G) -> 24.807838
A16: A4F9A338 | B16: 45329 | C16: East | D16: Groceries | E16: 1081.62 | F16: 4 | G16: 19 | H16: 611.06
A17: EADCEAA8 | B17: 45318 | C17: East | D17: Furniture | E17: 3455.67 | F17: 39 | G17: 21 | H17: 208.1
A18: AD7F9DE9 | B18: 45078 | C18: South | D18: Groceries | E18: 2381.51 | F18: 16 | G18: 39 | H18: 1083.96
A19: 35358E9C | B19: 45471 | C19: North | D19: Clothings | E19: 2784.79 | F19: 35 | G19: 40 | H19: 999.6
A20: 31676338 | B20: 45246 | C20: South | D20: Clothings | E20: 1082.98 | F20: 8 | G20: 11 | H20: 1604.19 | J20: Average Profit by category
A21: 05D72E20 | B21: 45556 | C21: East | D21: Clothings | E21: 787.79 | F21: 47 | G21: 18 | H21: 1313.33
A22: 68DBE328 | B22: 45566 | C22: South | D22: Furniture | E22: 312.7 | F22: 36 | G22: 43 | H22: 559.52 | J22: Groceries | K22: =AVERAGEIF(D:D,D2,H:H) -> 1006.2658
A23: 78D3F47B | B23: 45077 | C23: East | D23: Sports | E23: 265.32 | F23: 21 | G23: 36 | H23: 595.91 | J23: Clothings | K23: =AVERAGEIF(D:D,D6,H:H) -> 1011.2806
A24: 9E4D1FE0 | B24: 45400 | C24: West | D24: Furniture | E24: 1253.64 | F24: 35 | G24: 14 | H24: 1653.66 | J24: Furniture | K24: =AVERAGEIF(D:D,D7,H:H) -> 1023.3827
A25: 9215A70E | B25: 45341 | C25: West | D25: Clothings | E25: 1874.07 | F25: 28 | G25: 23 | H25: 1783.26 | J25: Sports | K25: =AVERAGEIF(D:D,D8,H:H) -> 1007.5921
A26: 54CA3433 | B26: 45041 | C26: East | D26: Clothings | E26: 2561.71 | F26: 44 | G26: 10 | H26: =AVERAGE(H2:H25,H27:H4001) -> 1007.9759
A27: 0BA75CC7 | B27: 45059 | C27: West | D27: Sports | E27: 1960.74 | F27: 50 | G27: 6 | H27: 1530.61
A28: 601860B1 | B28: 45037 | C28: East | D28: Electronics | E28: 2415.44 | F28: 35 | G28: 14 | H28: 335.57
A29: E393E106 | B29: 45290 | C29: East | D29: Electronics | E29: 2284.22 | F29: 8 | G29: 41 | H29: 1866.59
A30: 7AB3D472 | B30: 44885 | C30: West | D30: Sports | E30: 2118.55 | F30: 29 | G30: 24 | H30: 702.15
A31: 01D9B1AE | B31: 45248 | C31: South | D31: Groceries | E31: 4803.6 | F31: 11 | G31: 12 | H31: 1086.74
A32: 20385CB6 | B32: 45533 | C32: North | D32: Groceries | E32: 4297 | F32: 17 | G32: 49 | H32: 678.7
A33: 2BFE58FA | B33: 45449 | C33: East | D33: Sports | E33: 804.64 | F33: 43 | G33: 1 | H33: 60.68
A34: 2800F598 | B34: 45228 | C34: West | D34: Clothings | E34: 2903.83 | F34: 16 | G34: 31 | H34: 27.53
A35: 97D3684E | B35: 45114 | C35: East | D35: Electronics | E35: 3436.78 | F35: 21 | G35: 27 | H35: 75.19
A36: 8A0CE327 | B36: 45557 | C36: South | D36: Electronics | E36: 581.5 | F36: 39 | G36: 34 | H36: 863
A37: 6ED01FA3 | B37: 45018 | C37: West | D37: Electronics | E37: 1939.1 | F37: 26 | G37: 47 | H37: 1273.29
A38: 1C109DD7 | B38: 44899 | C38: South | D38: Furniture | E38: 3252.47 | F38: 24 | G38: 4 | H38: 1643.65
... A4001: DA37CF04 | B4001: 45465 | C4001: East | D4001: Furniture | E4001: 2975.86 | F4001: 29 | G4001: 37 | H4001: 1870.61

Sheet Task 5
B2: Column Labels
B3: Clothings | D3: Electronics | F3: Furniture | H3: Groceries | J3: Sports | L3: Total Sum of Sales Amount | M3: Total Sum of Profit
A4: Row Labels | B4: Sum of Sales Amount | C4: Sum of Profit | D4: Sum of Sales Amount | E4: Sum of Profit | F4: Sum of Sales Amount | G4: Sum of Profit | H4: Sum of Sales Amount | I4: Sum of Profit | J4: Sum of Sales Amount | K4: Sum of Profit
A5: East | B5: 558307.99 | C5: 217360.53 | D5: 453722.85 | E5: 194570.42 | F5: 558116.9 | G5: 227380.53 | H5: 449735.78 | I5: 181843.68 | J5: 575612.96 | K5: 229704.77 | L5: 2595496.5 | M5: 1050859.9
A6: North | B6: 575975.88 | C6: 207145.82 | D6: 527159.55 | E6: 203772.53 | F6: 494993.63 | G6: 209391.78 | H6: 471913.51 | I6: 172529.97 | J6: 469626.43 | K6: 177465.97 | L6: 2539669 | M6: 970306.07
A7: South | B7: 529784.9 | C7: 224799.76 | D7: 492194.56 | E7: 188923.5 | F7: 487656.54 | G7: 189883.78 | H7: 496331.25 | I7: 211125.65 | J7: 488444.03 | K7: 196169.86 | L7: 2494411.3 | M7: 1010902.5
A8: West | B8: 491938.81 | C8: 206240.56 | D8: 574757.97 | E8: 216391.51 | F8: 508729.09 | G8: 208424.23 | H8: 446244.52 | I8: 174106.08 | J8: 458536.54 | K8: 193664.76 | L8: 2480206.9 | M8: 998827.14
A9: Grand Total | B9: 2156007.6 | C9: 855546.67 | D9: 2047834.9 | E9: 803657.96 | F9: 2049496.2 | G9: 835080.32 | H9: 1864225.1 | I9: 739605.38 | J9: 1992220 | K9: 797005.36 | L9: 10109784 | M9: 4030895.7

Sheet Task 6
L4: Row Labels | M4: Sum of Sales Amount
L5: East | M5: 2595496.5
L6: North | M6: 2539669
L7: South | M7: 2494411.3
L8: West | M8: 2480206.9
L9: Grand Total | M9: 10109784
F24: Row Labels | G24: Sum of Sales Amount
F25: Clothings | G25: 2156007.6
F26: Electronics | G26: 2047834.9
F27: Furniture | G27: 2049496.2
F28: Groceries | G28: 1864225.1
F29: Sports | G29: 1992220
F30: Grand Total | G30: 10109784

Sheet Task 1
A1: Order id | B1: Order Date | C1: Region | D1: Product Category | E1: Sales Amount | F1: Quantity Sold | G1: Discount (%) | H1: Profit

Sheet Dashboard
BD2: Analyzing and Visualizing Regional Sales Performance
BD11: Total Sale | EB11: Total Profit
BD17: =SUM('Task 2'!E:E) -> 10109784 | EB17: =SUM('Task 2'!H:H) -> 4031903.7
DF19: s
